# 47장 에러 처리

스터디 날짜: 2022년 11월 24일
완료 여부 : Done
작성자: 익명

기본적으로 에러 처리를 구현하는 방법은 크게 두 가지가 있다. if 문이나 단축 평가 또는 옵셔널 체이닝 연산자를 통해 확인해서 처리하는 방법과 try...catch...finally 문이 있다. 

```jsx
try{
  // 실행할 코드(에러가 발생할 가능성이 있는 코드)
} catch (err) {
  // try 코드 블록에서 에러가 발생하면 이 코드 블록의 코드가 실행된다.
  // err에는 try 코드 블록에서 발생한 Error 객체가 전달된다.
} finally {
  // 에러 발생과 상관없이 반드시 한 번 실행된다.  
}
```

**옵셔널 체이닝(?.)**은 **체이닝(.)**과 동일한 기능을 하는데 차이점은 옵셔널 체이닝은 **nullish**한**(null or undefined)** 값을 할당하고 있는 경우에 에러를 반환하지 않고 **undefined**를 반환합니다.

```jsx
let users = {}

console.log(users.user.name); //TypeError: Cannot read property 'name' of undefined
console.log(users.user?.name) //undefined
```

하지만 위 경우에서 **옵셔널 체이닝**을 사용하면 에러가 발생하지 않고 **undefined**가 출력됩니다.

따라서 값이 누락될 가능성이 있는 경우에 **옵셔널 체이닝**을 사용하면 프로그램의 안정성을 높일 수 있고 보다 간단하게 표현할 수 있습니다.

# **Error 객체**

Error 생성자 함수는 에러 객체를 생성한다. Error 생성자 함수에는 에러를 상세히 설명하는 에러 메세지를 인수로 전달할 수 있다.

자바스크립트는 Error 생성자 함수를 포함해 7가지의 에러 객체를 생성할 수 있는 Error 생성자 함수를 제공한다. SyntaxError, ReferenceError, TypeError, RangeError, URIError, EvalError 생성자 함수가 생성한 에러 객체의 프로토타입은 모두 Error.prototype을 상속받는다.

# **throw 문**

Error 생성자 함수로 에러 객체를 생성한다고 에러가 발생하는 것은 아니다. 즉, 에러 객체 생성과 에러 발생은 의미가 다르다.

```jsx
try {
  // 에러 객체를 생성한다고 에러가 발생하는 것은 아니다.
  new Error('something wrong');
} catch (error) {
  console.log(error);
}
```

에러를 발생시키려면 try 코드 블록에서 throw 문으로 에러 객체를 던져야 한다.

에러를 던지면 catch 문의 에러 변수가 생성되고 던져진 에러 객체가 할당된다. 그리고 catch 코드 블록이 실행 된다.

```jsx
try {
  // 에러 객체를 던지면 catch 코드 블록이 실행되기 시작한다.
  throw new Error('something wrong');
} catch (error) {
  console.log(error); // Error: something wrong
}
```

# **에러의 전파**

에러는 호출자 방향으로 전파된다. 즉, 콜 스택의 아래 방향(실행 중인 실행 컨텍스트가 푸시되기 직전에 푸시된 실행 컨텍스트 방향)으로 전파된다.

```jsx
const foo = () => {
  throw Error('foo에서 발생한 에러'); // ④ 4
};

const bar = () => {
  foo(); // ③ 3
};

const baz = () => {
  bar(); // ② 2
};

try {
  baz(); // ① 1
} catch (err) {
  console.error(err);
}
```

①에서 baz 함수를 호출하면 ②에서 bar 함수가 호출되고 ③에서 foo함수가 호출되고 foo 함수는 ④에서 에러를 throw한다. 이때 foo 함수가 throw한 에러는 다음과 같이 호출자에게 전파되어 전역에서 캐치된다.

![Untitled](47%E1%84%8C%E1%85%A1%E1%86%BC%20%E1%84%8B%E1%85%A6%E1%84%85%E1%85%A5%20%E1%84%8E%E1%85%A5%E1%84%85%E1%85%B5%20f06a4b9b75324b46b8094c5159128c2a/Untitled.png)

이처럼 throw된 에러를 캐치하지 않으면 호출자 방향으로 전파된다. 이때 throw된 에러를 캐치하여

적절히 대응하면 프로그램을 강제 종료시키지 않고 코드의 실행 흐름을 복구할 수 있다. throw된 에러를 어디에서도 캐치하지 않으면 프로그램은 강제 종료된다.